<?xml version="1.0"?>
<robot name="converted_model">
    <link name="link">
        <inertial>
            <mass value="0.5"/>
            <inertia 
                ixx="0.178326"
                ixy="0"
                ixz="0"
                iyy="0.516985"
                iyz="0"
                izz="0.645029"/>
            <origin xyz="0 0 0.4" rpy="0 0 0"/>
        </inertial>

        <visual>
            <geometry>
                <box size="2.1578 1.20422 0.487851"/>
            </geometry>
            <material name="Grey">
                <color rgba="0.7 0.7 0.7 1"/>
            </material>
            <origin xyz="0 0 0.4" rpy="0 0 0"/>
        </visual>

        <collision>
            <geometry>
                <box size="2.1578 1.20422 0.487851"/>
            </geometry>
            <origin xyz="0 0 0.4" rpy="0 0 0"/>
        </collision>
    </link>

    <link name="link_0">
        <inertial>
            <mass value="1"/>
            <inertia
            ixx="0.0277083"
            ixy="0"
            ixz="0"
            iyy="0.0277083"
            iyz="0"
            izz="0.045"/>
            <origin xyz="0 0 0" rpy="1.5707 0 0"/>
        </inertial>

        <visual>
            <geometry>
                <cylinder radius="0.3" length="0.25"/>
            </geometry>
            <origin xyz="0 0 0.4" rpy="1.5707 0 0"/>
            <material name="Grey">
                <color rgba="0.7 0.7 0.7 1"/>
            </material>
        </visual>

        <collision>
            <geometry>
                <cylinder radius="0.3" length="0.25"/>
            </geometry>
            <origin xyz="0 0 0.4" rpy="1.5707 0 0"/>
        </collision>
        </link>

    <link name="link_0_1">
        <inertial>
            <mass value="0.000979317"/>
            <inertia
            ixx="1.81124e-06"
            ixy="0"
            ixz="0"
            iyy="1.55802e-06"
            iyz="0"
            izz="1.52488e-06"/>
            <origin xyz="0 0 0" rpy="0 0 0"/>
        </inertial>

        <visual>
            <geometry>
                <box size="0.088267 0.104374 0.106301"/>
            </geometry>
            <origin xyz="0 0 0" rpy="0 0 0"/>
            <material name="Grey">
                <color rgba="0.7 0.7 0.7 1"/>
            </material>
        </visual>

        <collision>
            <geometry>
                <box size="0.088267 0.104374 0.106301"/>
            </geometry>
            <origin xyz="0 0 0" rpy="0 0 0"/>
        </collision>
    </link>

    <link name="link_0_clone">
        <inertial>
            <mass value="1"/>
            <inertia
            ixx="0.145833"
            ixy="0"
            ixz="0"
            iyy="0.145833"
            iyz="0"
            izz="0.125"/>
            <origin xyz="0 0 0" rpy="1.5707 0 0"/>
        </inertial>

        <visual>
            <geometry>
                <cylinder radius="0.3" length="0.25"/>
            </geometry>
            <origin xyz="0 0 0.4" rpy="1.5707 0 0"/>
            <material name="Grey">
                <color rgba="0.7 0.7 0.7 1"/>
            </material>
        </visual>

        <collision>
            <geometry>
                <cylinder radius="0.3" length="0.25"/>
            </geometry>
            <origin xyz="0 0 0.4" rpy="1.5707 0 0"/>
        </collision>
    </link>

    <link name="link_1">
        <inertial>
            <mass value="1"/>
            <inertia
            ixx="0.1"
            ixy="0"
            ixz="0"
            iyy="0.1"
            iyz="0"
            izz="0.1"/>
            <origin xyz="0 0 0" rpy="0 0 0"/>
        </inertial>

        <visual>
            <geometry>
                <sphere radius="0.2"/>
            </geometry>
            <origin xyz="0 0 0.2" rpy="0 0 0"/>
            <material name="Grey">
                <color rgba="0.7 0.7 0.7 1"/>
            </material>
        </visual>

        <collision>
            <geometry>
                <sphere radius="0.2"/>
            </geometry>
            <origin xyz="0 0 0.2" rpy="0 0 0"/>
        </collision>
    </link>


    <joint name="link_JOINT_0" type="fixed">
        <parent link="link"/>
        <child link="link_0_1"/>
        <origin xyz="0 0 0" rpy="0 0 0"/>
    </joint>

    <joint name="link_JOINT_2" type="revolute">
        <parent link="link"/>
        <child link="link_1"/>
        <origin xyz="0 0 0.2" rpy="0 0 0"/>
        <axis xyz="0 1 0"/>
        <limit effort="0" velocity="0"/>
        <dynamics damping="0" friction="0"/>
    </joint>

    <joint name="link_JOINT_3" type="revolute">
        <parent link="link"/>
        <child link="link_0"/>
        <origin xyz="0 0 0" rpy="0 0 0"/>
        <axis xyz="0 0 1"/>
        <limit lower="-1.79769e308" upper="1.79769e308" effort="0" velocity="0"/>
        <dynamics damping="0" friction="0"/>
    </joint>

    <joint name="link_JOINT_4" type="revolute">
        <parent link="link"/>
        <child link="link_0_clone"/>
        <origin xyz="0 0 0" rpy="0 0 0"/>
        <axis xyz="0 0 1"/>
        <limit lower="-1.79769e308" upper="1.79769e308" effort="0" velocity="0"/>
        <dynamics damping="0" friction="0"/>
    </joint>


    <gazebo reference="link_0_1">
        <sensor type="depth" name="depth_camera">
            <pose>0 0 0 0 0 0</pose>
            <update_rate>30</update_rate>
            <visualize>true</visualize>
            <camera>
                <horizontal_fov>1.047</horizontal_fov>
                <image>
                    <width>640</width>
                    <height>480</height>
                    <format>R8G8B8</format>
                </image>
                <clip>
                    <near>0.1</near>
                    <far>10</far>
                </clip>
            </camera>
            <plugin name="depth_camera_plugin" filename="libgazebo_ros_camera.so">
                <cameraName>depth_camera</cameraName>
                <imageTopicName>image_raw</imageTopicName>
                <cameraInfoTopicName>camera_info</cameraInfoTopicName>
                <depthImageTopicName>depth/image_raw</depthImageTopicName>
                <depthImageCameraInfoTopicName>depth/camera_info</depthImageCameraInfoTopicName>
                <pointCloudTopicName>depth/points</pointCloudTopicName>
                <frameName>camera_link</frameName>
                <hackBaseline>0.07</hackBaseline>
            </plugin>
        </sensor>
    </gazebo>

    <plugin name='gazebo_ros2_control' filename='libgazebo_ros2_control.so'>
        <parameters>/home/song/ros2_ws/src/follower/ros2_controller.yaml</parameters>
    </plugin>



</robot>
