<?xml version="1.0" ?>
<!-- =================================================================================== -->
<!-- |    This document was autogenerated by xacro from ../model_editor_models/model/robot_car.xacro | -->
<!-- |    EDITING THIS FILE BY HAND IS NOT RECOMMENDED                                 | -->
<!-- =================================================================================== -->
<robot name="robot_car">
  <link name="base_link">
    <visual>
      <geometry>
        <box size="2.2 1.4 0.3"/>
      </geometry>
      <origin rpy="0 0 0" xyz="0 0 0"/>
      <material name="gray">
        <color rgba="0.5 0.5 0.5 1"/>
      </material>
    </visual>
    <collision>
      <geometry>
        <box size="1.9 1.4 0.3"/>
      </geometry>
      <origin rpy="0 0 0" xyz="0 0 0"/>
      <surface>
        <friction>
          <ode>
            <mu>1.0</mu>
            <mu2>1.0</mu2>
          </ode>
        </friction>
      </surface>
    </collision>
    <inertial>
      <mass value="1.1"/>
      <inertia ixx="0.18791666666666668" ixy="0.0" ixz="0.0" iyy="0.45191666666666674" iyz="0.0" izz="0.6233333333333334"/>
      <origin rpy="0 0 0" xyz="0 0 0"/>
    </inertial>
  </link>
  <link name="left_wheel_steer">
    <visual>
      <geometry>
        <cylinder length="0.05" radius="0.15"/>
      </geometry>
      <origin rpy="1.5708 0 0" xyz="0 0 0"/>
      <material name="gray">
        <color rgba="0.5 0.5 0.5 1"/>
      </material>
    </visual>
    <collision>
      <geometry>
        <cylinder length="0.05" radius="0.15"/>
      </geometry>
      <surface>
        <friction>
          <ode>
            <mu>1</mu>
            <mu2>1</mu2>
          </ode>
        </friction>
      </surface>
      <origin rpy="1.5708 0 0" xyz="0 0 0"/>
    </collision>
    <inertial>
      <mass value="0.8"/>
      <inertia ixx="0.004666666666666666" ixy="0" ixz="0" iyy="0.004666666666666666" iyz="0" izz="0.009"/>
      <origin rpy="0 0 0" xyz="0 0 0"/>
    </inertial>
  </link>
  <link name="right_wheel_steer">
    <visual>
      <geometry>
        <cylinder length="0.05" radius="0.15"/>
      </geometry>
      <origin rpy="1.5708 0 0" xyz="0 0 0"/>
      <material name="gray">
        <color rgba="0.5 0.5 0.5 1"/>
      </material>
    </visual>
    <collision>
      <geometry>
        <cylinder length="0.05" radius="0.15"/>
      </geometry>
      <surface>
        <friction>
          <ode>
            <mu>1</mu>
            <mu2>1</mu2>
          </ode>
        </friction>
      </surface>
      <origin rpy="1.5708 0 0" xyz="0 0 0"/>
    </collision>
    <inertial>
      <mass value="0.8"/>
      <inertia ixx="0.004666666666666666" ixy="0" ixz="0" iyy="0.004666666666666666" iyz="0" izz="0.009"/>
      <origin rpy="0 0 0" xyz="0 0 0"/>
    </inertial>
  </link>
  <link name="left_wheel">
    <visual>
      <geometry>
        <cylinder length="0.2" radius="0.35"/>
      </geometry>
      <origin rpy="1.5708 0 0" xyz="0 0 0"/>
      <material name="gray">
        <color rgba="0.5 0.5 0.5 1"/>
      </material>
    </visual>
    <collision>
      <geometry>
        <cylinder length="0.2" radius="0.35"/>
      </geometry>
      <surface>
        <friction>
          <ode>
            <mu>1</mu>
            <mu2>1</mu2>
          </ode>
        </friction>
      </surface>
      <origin rpy="1.5708 0 0" xyz="0 0 0"/>
    </collision>
    <inertial>
      <mass value="0.8"/>
      <inertia ixx="0.027166666666666665" ixy="0" ixz="0" iyy="0.027166666666666665" iyz="0" izz="0.048999999999999995"/>
      <origin rpy="0 0 0" xyz="0 0 0"/>
    </inertial>
  </link>
  <link name="right_wheel">
    <visual>
      <geometry>
        <cylinder length="0.2" radius="0.35"/>
      </geometry>
      <origin rpy="1.5708 0 0" xyz="0 0 0"/>
      <material name="gray">
        <color rgba="0.5 0.5 0.5 1"/>
      </material>
    </visual>
    <collision>
      <geometry>
        <cylinder length="0.2" radius="0.35"/>
      </geometry>
      <surface>
        <friction>
          <ode>
            <mu>1</mu>
            <mu2>1</mu2>
          </ode>
        </friction>
      </surface>
      <origin rpy="1.5708 0 0" xyz="0 0 0"/>
    </collision>
    <inertial>
      <mass value="0.8"/>
      <inertia ixx="0.027166666666666665" ixy="0" ixz="0" iyy="0.027166666666666665" iyz="0" izz="0.048999999999999995"/>
      <origin rpy="0 0 0" xyz="0 0 0"/>
    </inertial>
  </link>
  <link name="sphere">
    <visual>
      <geometry>
        <sphere radius="0.25"/>
      </geometry>
      <origin rpy="1.5708 0 0" xyz="0 0 0"/>
      <material name="gray">
        <color rgba="0.5 0.5 0.5 1"/>
      </material>
    </visual>
    <collision>
      <geometry>
        <sphere radius="0.25"/>
      </geometry>
      <surface>
        <friction>
          <ode>
            <mu>1.0</mu>
            <mu2>1.0</mu2>
          </ode>
        </friction>
      </surface>
      <origin rpy="1.5708 0 0" xyz="0 0 0"/>
    </collision>
    <inertial>
      <mass value="1.0"/>
      <inertia ixx="0.025" ixy="0" ixz="0" iyy="0.025" iyz="0" izz="0.025"/>
      <origin rpy="0 0 0" xyz="0 0 0"/>
    </inertial>
  </link>
  <!-- Depth camera link -->
  <link name="depth_camera_link">
    <visual>
      <geometry>
        <box size="0.05 0.05 0.05"/>
        <!-- camera size -->
      </geometry>
      <material name="black">
        <color rgba="0.0 0.0 0.0 1.0"/>
      </material>
    </visual>
    <inertial>
      <mass value="0.1"/>
      <origin rpy="0 0 0" xyz="0 0 0"/>
      <inertia ixx="1e-5" ixy="0" ixz="0" iyy="1e-5" iyz="0" izz="1e-5"/>
    </inertial>
  </link>
  <joint name="left_body_steer" type="revolute">
    <parent link="base_link"/>
    <child link="left_wheel_steer"/>
    <origin rpy="0 0 0" xyz="0.5 0.8 0.0"/>
    <axis xyz="0 0 1"/>
    <limit effort="1" lower="-1.57" upper="1.57" velocity="1"/>
  </joint>
  <joint name="right_body_steer" type="revolute">
    <parent link="base_link"/>
    <child link="right_wheel_steer"/>
    <origin rpy="0 0 0" xyz="0.5 -0.8 0.0"/>
    <axis xyz="0 0 1"/>
    <limit effort="1" lower="-1.57" upper="1.57" velocity="1"/>
  </joint>
  <joint name="left_body_wheel" type="continuous">
    <parent link="left_wheel_steer"/>
    <child link="left_wheel"/>
    <origin rpy="0 0 0" xyz="0 0 0"/>
    <axis xyz="0 1 0"/>
    <limit effort="1" velocity="5"/>
  </joint>
  <joint name="right_body_wheel" type="continuous">
    <parent link="right_wheel_steer"/>
    <child link="right_wheel"/>
    <origin rpy="0 0 0" xyz="0.0 0.0 0.0"/>
    <axis xyz="0 1 0"/>
    <limit effort="1" velocity="5"/>
  </joint>
  <joint name="body_sphere" type="continuous">
    <parent link="base_link"/>
    <child link="sphere"/>
    <origin rpy="0 0 0" xyz="-0.7 0 -0.15"/>
    <axis xyz="0 1 0"/>
    <limit effort="10" velocity="10"/>
  </joint>
  <!-- Fixed joint attaching the camera to the robot -->
  <joint name="depth_camera_joint" type="fixed">
    <parent link="base_link"/>
    <!-- or wherever you want to mount it -->
    <child link="depth_camera_link"/>
    <origin rpy="0 0 0" xyz="1.0 0 0.3"/>
    <!-- Adjust position -->
  </joint>
  <ros2_control name="GazeboSystem" type="system">
    <hardware>
      <plugin>gazebo_ros2_control/GazeboSystem</plugin>
    </hardware>
    <joint name="left_body_steer">
      <command_interface name="position"/>
      <state_interface name="position"/>
    </joint>
    <joint name="right_body_steer">
      <command_interface name="position"/>
      <state_interface name="position"/>
    </joint>
    <joint name="body_sphere">
      <command_interface name="velocity"/>
      <state_interface name="velocity"/>
    </joint>
  </ros2_control>
  <gazebo>
    <plugin filename="libgazebo_ros2_control.so" name="gazebo_ros2_control">
      <parameters>/home/song/ros2_ws/src/follower/ros2_controller.yaml</parameters>
    </plugin>
  </gazebo>
  <gazebo reference="depth_camera_link">
    <sensor name="depth_camera" type="depth">
      <always_on>true</always_on>
      <update_rate>30.0</update_rate>
      <visualize>true</visualize>
      <camera>
        <horizontal_fov>1.047</horizontal_fov>
        <!-- ~60 degrees -->
        <image>
          <width>640</width>
          <height>480</height>
          <format>R8G8B8</format>
        </image>
        <clip>
          <near>0.1</near>
          <far>10.0</far>
        </clip>
      </camera>
      <plugin filename="libgazebo_ros_camera.so" name="gazebo_ros_depth_camera">
        <ros>
          <namespace>/</namespace>
        </ros>
        <camera_name>depth_camera</camera_name>
        <frame_name>depth_camera_link</frame_name>
        <image_topic_name>image_raw</image_topic_name>
        <depth_image_topic_name>depth/image_raw</depth_image_topic_name>
        <camera_info_topic_name>camera_info</camera_info_topic_name>
      </plugin>
    </sensor>
  </gazebo>
</robot>
